Connected to pydev debugger (build 243.25659.43)
Traceback (most recent call last):
  File "D:\Desktop\test-main\.venv\Lib\site-packages\modelscope\utils\import_utils.py", line 462, in _get_module
    return importlib.import_module('.' + module_name, self.__name__)
           ^^^^^^^^^^^^^^^^^^^^^^^^^^^^^^^^^^^^^^^^^^^^^^^^^^^^^^^^^
  File "D:\code\anaconda3\Lib\importlib\__init__.py", line 90, in import_module
    return _bootstrap._gcd_import(name[level:], package, level)
           ^^^^^^^^^^^^^^^^^^^^^^^^^^^^^^^^^^^^^^^^^^^^^^^^^^^^
  File "<frozen importlib._bootstrap>", line 1387, in _gcd_import
  File "<frozen importlib._bootstrap>", line 1360, in _find_and_load
  File "<frozen importlib._bootstrap>", line 1331, in _find_and_load_unlocked
  File "<frozen importlib._bootstrap>", line 935, in _load_unlocked
  File "<frozen importlib._bootstrap_external>", line 995, in exec_module
  File "<frozen importlib._bootstrap>", line 488, in _call_with_frames_removed
  File "D:\Desktop\test-main\.venv\Lib\site-packages\modelscope\pipelines\__init__.py", line 4, in <module>
    from .base import Pipeline
  File "D:\Desktop\test-main\.venv\Lib\site-packages\modelscope\pipelines\base.py", line 16, in <module>
    from modelscope.msdatasets import MsDataset
  File "D:\Desktop\test-main\.venv\Lib\site-packages\modelscope\msdatasets\__init__.py", line 2, in <module>
    from modelscope.msdatasets.ms_dataset import MsDataset
  File "D:\Desktop\test-main\.venv\Lib\site-packages\modelscope\msdatasets\ms_dataset.py", line 25, in <module>
    from modelscope.msdatasets.utils.hf_datasets_util import load_dataset_with_ctx
  File "D:\Desktop\test-main\.venv\Lib\site-packages\modelscope\msdatasets\utils\hf_datasets_util.py", line 19, in <module>
    from datasets.data_files import (
ImportError: cannot import name 'get_metadata_patterns' from 'datasets.data_files' (D:\Desktop\test-main\.venv\Lib\site-packages\datasets\data_files.py). Did you mean: '_get_metadata_files_patterns'?
The above exception was the direct cause of the following exception:
Traceback (most recent call last):
  File "D:\code\PyCharm 2024.3.4\plugins\python-ce\helpers\pydev\pydevd.py", line 1570, in _exec
    pydev_imports.execfile(file, globals, locals)  # execute the script
    ^^^^^^^^^^^^^^^^^^^^^^^^^^^^^^^^^^^^^^^^^^^^^
  File "D:\code\PyCharm 2024.3.4\plugins\python-ce\helpers\pydev\_pydev_imps\_pydev_execfile.py", line 18, in execfile
    exec(compile(contents+"\n", file, 'exec'), glob, loc)
  File "D:\Desktop\test-main\main.py", line 61, in <module>
    from modelscope import pipeline
  File "<frozen importlib._bootstrap>", line 1412, in _handle_fromlist
  File "D:\Desktop\test-main\.venv\Lib\site-packages\modelscope\utils\import_utils.py", line 437, in __getattr__
    module = self._get_module(self._class_to_module[name])
             ^^^^^^^^^^^^^^^^^^^^^^^^^^^^^^^^^^^^^^^^^^^^^
  File "D:\Desktop\test-main\.venv\Lib\site-packages\modelscope\utils\import_utils.py", line 464, in _get_module
    raise RuntimeError(
RuntimeError: Failed to import modelscope.pipelines because of the following error (look up to see its traceback):
cannot import name 'get_metadata_patterns' from 'datasets.data_files' (D:\Desktop\test-main\.venv\Lib\site-packages\datasets\data_files.py)
python-BaseException